<robot name = "robot">
    <link name="root">
        <inertial>
            <origin xyz="0 0 1" rpy="0 0 0"/>
            <mass value="1" />
            <inertia ixx="100" ixy="0" ixz="0" iyy="100" iyz="0" izz="100" />
        </inertial>
        <visual>
            <origin xyz="0 0 1" rpy="0 0 0"/>
            <geometry>
                <box size="0.15857297777183457 0.8093003777894173 0.3587154793099988" />
            </geometry>
            <material name="Cyan">
                <color rgba="0 1.0 1.0 1.0"/>
            </material>
        </visual>
        <collision>
            <origin xyz="0 0 1" rpy="0 0 0"/>
            <geometry>
                <box size="0.15857297777183457 0.8093003777894173 0.3587154793099988" />
            </geometry>
        </collision>
    </link>
    <joint name="root_A00" type="revolute">
       <parent link="root"/>
       <child  link="A0"/>
       <origin rpy="0 0 0" xyz="0 -0.40465018889470866 1.1793577396549995" />
     <axis xyz="1 0 0"/>
       <limit effort="0.0" lower="-3.14159" upper="3.14159" velocity="0.0"/>
    </joint>
    <link name="A0">
        <inertial>
            <origin xyz="0 -0.15514206941482225 0.565058664630606" rpy="0 0 0"/>
            <mass value="1" />
            <inertia ixx="100" ixy="0" ixz="0" iyy="100" iyz="0" izz="100" />
        </inertial>
        <visual>
            <origin xyz="0 -0.15514206941482225 0.565058664630606" rpy="0 0 0"/>
            <geometry>
                <box size="0.7093969530252437 0.3102841388296445 1.130117329261212" />
            </geometry>
            <material name="Green">
                <color rgba="0 1.0 0 1.0"/>
            </material>
        </visual>
        <collision>
            <origin xyz="0 -0.15514206941482225 0.565058664630606" rpy="0 0 0"/>
            <geometry>
                <box size="0.7093969530252437 0.3102841388296445 1.130117329261212" />
            </geometry>
        </collision>
    </link>
    <joint name="root_A10" type="revolute">
       <parent link="root"/>
       <child  link="A1"/>
       <origin rpy="0 0 0" xyz="0 -0.40465018889470866 1" />
     <axis xyz="0 0 1"/>
       <limit effort="0.0" lower="-3.14159" upper="3.14159" velocity="0.0"/>
    </joint>
    <link name="A1">
        <inertial>
            <origin xyz="0 -0.5230048823250405 0" rpy="0 0 0"/>
            <mass value="1" />
            <inertia ixx="100" ixy="0" ixz="0" iyy="100" iyz="0" izz="100" />
        </inertial>
        <visual>
            <origin xyz="0 -0.5230048823250405 0" rpy="0 0 0"/>
            <geometry>
                <box size="0.7023921877782966 1.046009764650081 0.5607741754501266" />
            </geometry>
            <material name="Cyan">
                <color rgba="0 1.0 1.0 1.0"/>
            </material>
        </visual>
        <collision>
            <origin xyz="0 -0.5230048823250405 0" rpy="0 0 0"/>
            <geometry>
                <box size="0.7023921877782966 1.046009764650081 0.5607741754501266" />
            </geometry>
        </collision>
    </link>
    <joint name="root_A20" type="revolute">
       <parent link="root"/>
       <child  link="A2"/>
       <origin rpy="0 0 0" xyz="0.07928648888591729 0 1" />
     <axis xyz="0 0 1"/>
       <limit effort="0.0" lower="-3.14159" upper="3.14159" velocity="0.0"/>
    </joint>
    <link name="A2">
        <inertial>
            <origin xyz="0.4468692981691571 0 0" rpy="0 0 0"/>
            <mass value="1" />
            <inertia ixx="100" ixy="0" ixz="0" iyy="100" iyz="0" izz="100" />
        </inertial>
        <visual>
            <origin xyz="0.4468692981691571 0 0" rpy="0 0 0"/>
            <geometry>
                <box size="0.8937385963383142 0.8727827706220487 1.4661171874385208" />
            </geometry>
            <material name="Green">
                <color rgba="0 1.0 0 1.0"/>
            </material>
        </visual>
        <collision>
            <origin xyz="0.4468692981691571 0 0" rpy="0 0 0"/>
            <geometry>
                <box size="0.8937385963383142 0.8727827706220487 1.4661171874385208" />
            </geometry>
        </collision>
    </link>
    <joint name="root_A30" type="revolute">
       <parent link="root"/>
       <child  link="A3"/>
       <origin rpy="0 0 0" xyz="0 0 1.1793577396549995" />
     <axis xyz="1 0 0"/>
       <limit effort="0.0" lower="-3.14159" upper="3.14159" velocity="0.0"/>
    </joint>
    <link name="A3">
        <inertial>
            <origin xyz="0 0 0.5580435760477584" rpy="0 0 0"/>
            <mass value="1" />
            <inertia ixx="100" ixy="0" ixz="0" iyy="100" iyz="0" izz="100" />
        </inertial>
        <visual>
            <origin xyz="0 0 0.5580435760477584" rpy="0 0 0"/>
            <geometry>
                <box size="0.166820705534453 0.7637863357001229 1.116087152095517" />
            </geometry>
            <material name="Cyan">
                <color rgba="0 1.0 1.0 1.0"/>
            </material>
        </visual>
        <collision>
            <origin xyz="0 0 0.5580435760477584" rpy="0 0 0"/>
            <geometry>
                <box size="0.166820705534453 0.7637863357001229 1.116087152095517" />
            </geometry>
        </collision>
    </link>
</robot>